Workbook

Sheet Sheet1
A1: Aircraft Company | B1: Aircraft name | C1: Passengers | D1: Max Takeoff Mass (kg) | E1: Operational Empty Mass (kg) | F1: Max Payload Range (km) | G1: Max Payload (kg) | H1: Take Off Distance (m) | I1: Landing Distance (m) | J1: wing surface area (m2) | K1: Taper Ratio | L1: 1/4 chord Sweep | M1: Aspect ratio | N1: Control surface area | O1: Thrust (kN) | P1: Cruise Mach number | Q1: Cruise Altitude for mach number(ft) | R1: Ceiling | S1: Max payload range | T1: T/W | U1: Source:
A2: Required | B2: Reference | C2: 150 | F2: 3700 | G2: TBD | H2: 2000 | I2: 1400 | J2: TBD | K2: TBD | L2: TBD | M2: TBD | N2: TBD | O2: TBD | P2: >0.6 | Q2: >12000 | T2: TBD
A3: Boeing | B3: 737-500 | C3: 145 | D3: 52390 | E3: 30960 | F3: 2518.72 | G3: 15530 | H3: 1832 | I3: 1362 | J3: 91 | K3: 0.24 | L3: 25 | M3: 9.17 | N3: ? | O3: 82.3 | P3: 0.737 | Q3: 26000 | R3: FL350 | U3: https://booksite.elsevier.com/9780340741528/appendices/data-a/table-2/table.htm
B4: 737-300 | C4: 149 | D4: 56470 | E4: 31869 | F4: 2922.456 | G4: 16030 | H4: 1939 | I4: 1396 | J4: 91.04 | K4: 0.24 | L4: 25.00 | M4: 9.17 | N4: ? | O4: 234 | P4: 0.74 | Q4: 26000 | U4: http://www.boeing.com/assets/pdf/commercial/airports/acaps/737.pdf, https://en.wikipedia.org/wiki/Boeing_737_Next_Generation#:~:text=Modifications%20to%20the%20737%2D800,174%2C100%20lb%20(79%2C000%20kg)., https://booksite.elsevier.com/9780340741528/appendices/data-a/default.htm, https://modernairliners.com/boeing-737/boeing-737-specifications/
B5: 737-8MAX | C5: 170 | D5: 82190 | E5: 45070 | F5: 6570 | G5: 20882 | H5: 2500 | I5: 1580 | J5: 127 | L5: 25.03 | M5: 10.159 | N5: ? | O5: 238-260 | P5: 0.785 | Q5: FL350 | R5: 410 | U5: https://www.boeing.com/resources/boeingdotcom/commercial/airports/acaps/737MAX_RevA.pdf, https://en.wikipedia.org/wiki/Boeing_737, https://booksite.elsevier.com/9780340741528/appendices/data-a/default.htm, https://modernairliners.com/boeing-737/boeing-737-specifications/
B6: 737-9MAX | C6: 180 | D6: 88314 | E6: 47490 | F6: 6570 | G6: 20240 | J6: 127 | L6: 25.03 | M6: 10.159 | N6: ? | O6: 238-260 | P6: 0.785 | Q6: FL350 | R6: 410 | U6: https://www.boeing.com/resources/boeingdotcom/commercial/airports/acaps/737MAX_RevA.pdf, https://en.wikipedia.org/wiki/Boeing_737, https://booksite.elsevier.com/9780340741528/appendices/data-a/default.htm, https://modernairliners.com/boeing-737/boeing-737-specifications/
B7: 737-700 | C7: 149 | D7: 69400 | E7: 37585 | F7: 5570 | G7: 11610 | H7: 2042 | I7: 1356 | J7: 124.6 | K7: 0.278 | L7: 25 | M7: 9.44 | N7: ? | O7: 89 | P7: 0.781 | Q7: 39000 | U7: https://booksite.elsevier.com/9780340741528/appendices/data-a/table-2/default.htm
A8: Airbus | B8: A319 | C8: 140 | D8: 64000 | E8: 39200 | F8: 2509.46 | G8: 11780 | H8: 1750 | I8: 1350 | J8: 122.4 | K8: 0.24 | L8: 25 | M8: 9.39 | N8: ? | O8: 98-120 | P8: 0.78 | R8: FL410 | U8: https://booksite.elsevier.com/9780340741528/appendices/data-a/table-1/table.htm | V8: https://www.airbus.com/aircraft/passenger-aircraft/a320-family/a320ceo.html
B9: A320 | C9: 155 | D9: 73500 | E9: 41310 | F9: 5639 | G9: 14250 | H9: 2180 | I9: 1440 | J9: 122.4 | K9: 0.24 | L9: 25 | M9: 9.39 | N9: ? | O9: 111-120 | P9: 0.78 | R9: FL410 | U9: https://booksite.elsevier.com/9780340741528/appendices/data-a/table-1/table.htm
B10: A320neo | C10: 194 | D10: 79000 | E10: 44300 | F10: 6300 | G10: 20000 | H10: 2090 | I10: 1400 | J10: 122.6 | K10: 0.24 | L10: 29 | M10: 9.39 | O10: 120.6 | P10: 0.82 | Q10: FL370 | R10: FL398 | U10: https://www.airbus.com/aircraft/passenger-aircraft/a320-family/a320neo.html, https://en.wikipedia.org/wiki/Airbus_A320neo_family#A320neo, https://modernairliners.com/airbus-a320-introduction/airbus-a320-specs/, https://booksite.elsevier.com/9780340741528/appendices/data-a/table-1/table.htm
B11: A220-300 | C11: 150 | D11: 69900 | E11: 37080 | F11: 3704 | G11: 18700 | H11: 1890 | I11: 1509 | J11: 112.3 | M11: 10.970703 | O11: 93.4-103.6 | P11: 0.78 | U11: https://www.airbus.com/aircraft/passenger-aircraft/a220-family/a220-300.html, https://en.wikipedia.org/wiki/Airbus_A220#cite_note-CS300APP-215
A12: Embraer | B12: E2-195 | C12: 146 | D12: 61500 | E12: 35700 | F12: 3500 | G12: 16150 | H12: 1,970 | I12: 1412 | J12: 103 | M12: =(35.13^2)/J12 -> 11.981717 | O12: 105.93 | P12: 0.78
A13: Sukhoi | B13: SSJ100 | C13: 103 | D13: 45880 | E13: 22425 | F13: 3048 | G13: 12245 | H13: 1731 | I13: 1630 | J13: 83.8 | O13: 137-143.2 | P13: 0.78 | R13: FL400 | U13: https://www.superjetinternational.com/wp-content/uploads/SSJ100_Datasheet.pdf
A14: DOUG | B14: DC 9-50 | C14: 139 | D14: 54420 | E14: 29300 | F14: 2520.6 | G14: 15265 | H14: 2362 | I14: 1439 | J14: 92.97 | K14: 0.206 | L14: 24 | M14: 8.72 | N14: ? | O14: 68.9 | P14: 0.75 | Q14: 27000 | R14: FL350 | U14: https://booksite.elsevier.com/9780340741528/appendices/data-a/table-5/table.htm
Q17: =AVERAGE(Q14,Q7,Q4,Q3,35000,35000,37000) -> 31000

Sheet DataBase
A1: NBR | B1: Aircraft Company | C1: Aircraft name | D1: Passengers | E1: Max Takeoff Mass (kg) | F1: Operational Empty Mass (kg) | G1: Max Payload Range (km) | H1: Design Range (km) | I1: Design Payload (kg) | J1: Take Off Distance (m) | K1: Landing Distance (m) | L1: Wing surface area (m2) | M1: Taper Ratio | N1: Sweep | O1: Aspect ratio | P1: Control surface area | Q1: Thrust (kN) | R1: Cruise Mach number | S1: Cruise Altitude for mach number(ft) | T1: Ceiling | U1: T/W | V1: Source:
A2: - | B2: Requirement | D2: 150 | E2: - | F2: - | G2: - | H2: 3700 | I2: =D2*H28 -> 15750 | J2: 2000 | K2: 1400 | L2: TBD | M2: TBD | N2: TBD | O2: TBD | P2: TBD | Q2: TBD | R2: >0.7 | S2: >12000 | U2: TBD
A3: 1 | B3: Embraer | C3: E2-195 | D3: 146 | E3: 61500 | F3: 35700 | H3: 3500 | I3: 16150 | J3: 1970 | K3: 1412 | L3: 103 | O3: =(35.13^2)/L3 -> 11.981717 | Q3: 105.93 | R3: 0.78
A4: 2 | B4: Airbus | C4: A319 | D4: 140 | E4: 64000 | F4: 39200 | G4: =CONVERT(1355,"Nmi","km") -> 2509.46 | H4: 3518 | I4: 11780 | J4: 1750 | K4: 1350 | L4: 122.4 | M4: 0.24 | N4: 25 | O4: 9.39 | P4: - | Q4: 110 | R4: 0.78 | T4: FL410 | V4: https://booksite.elsevier.com/9780340741528/appendices/data-a/table-1/table.htm
A5: 3 | B5: Airbus | C5: A320 | D5: 155 | E5: 73500 | F5: 41310 | G5: =CONVERT(2100,"Nmi","km") -> 3889.2 | H5: 5000 | I5: 14250 | J5: 2180 | K5: 1440 | L5: 122.4 | M5: 0.24 | N5: 25 | O5: 9.39 | P5: - | Q5: 120 | R5: 0.78 | T5: FL410 | V5: https://booksite.elsevier.com/9780340741528/appendices/data-a/table-1/table.htm
A6: 4 | B6: Airbus | C6: A220-300 | D6: 150 | E6: 69900 | F6: 37080 | G6: 3704 | H6: 6297 | I6: 18700 | J6: 1890 | K6: 1509 | L6: 112.3 | O6: 10.970703 | P6: - | Q6: 103.6 | R6: 0.78 | V6: https://www.airbus.com/aircraft/passenger-aircraft/a220-family/a220-300.htmlhttps://en.wikipedia.org/wiki/Airbus_A220#cite_note-CS300APP-215
A7: 5 | B7: McDonnell Douglas | C7: MD-81 | D7: 155 | E7: 63500 | F7: 35570 | G7: =CONVERT(1385,"Nmi","km") -> 2565.02 | H7: =CONVERT(1564,"Nmi","km") -> 2896.528 | I7: 17953 | J7: 2195 | K7: 1481 | L7: 112.3 | M7: 0.195 | N7: - | O7: 9.62 | P7: - | Q7: 85.6 | R7: 0.835 | S7: 27000 | V7: https://booksite.elsevier.com/9780340741528/appendices/data-a/table-5/table.htm
A8: 6 | B8: McDonnell Douglas | C8: MD-82 | D8: 155 | E8: 67812 | F8: 35630 | G8: =CONVERT(1860,"Nmi","km") -> 3444.72 | H8: =CONVERT(2050,"Nmi","km") -> 3796.6 | I8: 18802 | J8: 2274 | K8: 1500 | L8: 112.3 | M8: 0.195 | N8: - | O8: 9.62 | P8: - | Q8: 92.7 | R8: 0.835 | S8: 27000 | V8: https://booksite.elsevier.com/9780340741528/appendices/data-a/table-5/table.htm
A9: 7 | B9: McDonnell Douglas | C9: MD-83 | D9: 155 | E9: 72580 | F9: 36620 | G9: =CONVERT(2369,"Nmi","km") -> 4387.388 | H9: =CONVERT(2502,"Nmi","km") -> 4633.704 | I9: 18721 | J9: 2551 | K9: 1585 | L9: 112.3 | M9: 0.195 | N9: - | O9: 9.62 | P9: - | Q9: 96.5 | R9: 0.835 | S9: 27000 | V9: https://booksite.elsevier.com/9780340741528/appendices/data-a/table-5/table.htm
A10: 8 | B10: McDonnell Douglas | C10: MD-88 | D10: 155 | E10: 75580 | F10: 38740 | G10: 3800 | H10: 4600 | I10: 16600 | J10: 2400 | K10: 1585 | L10: 112 | M10: 0.2 | N10: - | O10: 9.62 | P10: - | Q10: 93.4 | R10: 0.708 | S10: 27000 | T10: FL370
A11: 9 | B11: McDonnell Douglas | C11: MD-90-30 | D11: 153 | E11: 70760 | F11: 39415 | G11: - | H11: =CONVERT(2275,"Nmi","km") -> 4213.3 | I11: 17350 | J11: 2135 | K11: 1564 | L11: 112.3 | M11: 0.195 | N11: - | O11: 9.62 | P11: - | Q11: 111.2 | R11: 0.809 | S11: 31000 | T11: - | U11: 0.32 | V11: https://booksite.elsevier.com/9780340741528/appendices/data-a/table-6/table.htm
A12: 10 | B12: McDonnell Douglas | C12: DC 9-50 | D12: 139 | E12: 54420 | F12: 29300 | G12: 2520.6 | H12: 2778 | I12: 15265 | J12: 2362 | K12: 1439 | L12: 92.97 | M12: 0.206 | O12: 8.72 | P12: - | Q12: 68.9 | R12: 0.75 | S12: 27000
A13: 11 | B13: Tupolev | C13: 204–300 | D13: 156 | E13: 107000 | F13: =57460 -> 57460 | G13: 5800 | H13: - | I13: 18000 | J13: 1870 | K13: - | L13: 184.2 | M13: - | N13: - | O13: - | P13: - | Q13: 158.2 | R13: - | S13: - | T13: FL39
A14: 12 | B14: Tupolev | C14: Tu-154M | D14: 154 | E14: 100000 | F14: 55300 | G14: =CONVERT(2019,"Nmi","km") -> 3739.188 | H14: =CONVERT(2805,"Nmi","km") -> 5194.86 | I14: 18000 | J14: 2100 | K14: 2060 | L14: 201.45 | M14: 0.267 | N14: - | O14: 7 | P14: - | Q14: 104 | R14: 0.875 | S14: 31000 | T14: FL350 | U14: 0.318 | V14: https://booksite.elsevier.com/9780340741528/appendices/data-a/table-7/table.htm
A15: 13 | B15: Boeing | C15: 737-700 | D15: 149 | E15: 69400 | F15: 37585 | G15: 5570 | H15: =CONVERT(3197,"Nmi","km") -> 5920.844 | I15: 11610 | J15: 2042 | K15: 1356 | L15: 124.6 | M15: 0.278 | N15: 25 | O15: 9.44 | P15: - | Q15: 117 | R15: 0.781 | S15: 39000 | T15: FL410
A16: 14 | B16: Boeing | C16: 737-300 | D16: 149 | E16: 56470 | F16: 31869 | G16: 2922.456 | H16: =CONVERT(2850,"Nmi","km") -> 5278.2 | I16: 16030 | J16: 1939 | K16: 1396 | L16: 91.04 | M16: 0.24 | N16: 25.00 | O16: 9.17 | P16: - | Q16: 100 | R16: 0.74 | S16: 26000 | T16: FL350
A17: 15 | B17: Boeing | C17: 737-500 | D17: 145 | E17: 52390 | F17: 30960 | G17: 2518.72 | H17: =CONVERT(1700,"Nmi","km") -> 3148.4 | I17: 15530 | J17: 1832 | K17: 1362 | L17: 91 | M17: 0.24 | N17: 25 | O17: 9.17 | P17: - | Q17: 100 | R17: 0.737 | S17: 26000 | T17: FL350
A18: 16 | B18: Airbus | C18: a319neo | D18: 150 | E18: 75500 | F18: 42600 | G18: 5000.4 | I18: 17700 | Q18: 107
B19: Average | D19: =AVERAGE(D3:D18) -> 150.375 | E19: =AVERAGE(E3:E18) -> 70894.5 | F19: =AVERAGE(F3:F18) -> 39021.188 | G19: =AVERAGE(G3:G18) -> 3910.8313 | H19: =AVERAGE(H3:H18) -> 4341.1026 | I19: =AVERAGE(I3:I18) -> 16402.562 | J19: =AVERAGE(J3:J18) -> 2108.5714 | K19: =AVERAGE(K3:K18) -> 1523.9167 | ... O19: =AVERAGE(O3:O18) -> 9.5509555 | Q19: =AVERAGE(Q3:Q18) -> 104.62687 | S19: =AVERAGE(S3:S18) -> 27666.667
B20: Design | E20: ='Class 1 Weight est.'!Q17 -> 80990.334 | F20: ='Class 1 Weight est.'!Q18 -> 63985.612 | H20: ='Class 1 Weight est.'!R26 -> 3700
E21: =(E20-E19)/E19*100 -> 14.240645 | F21: =(F20-F19)/F19*100 -> 63.976589 | G21: =(G20-G19)/G19*100 -> -100 | H21: =(H20-H19)/H19*100 -> -14.768197
G26: Name | H26: Value | I26: Unit | J26: Note
G27: per pax mass | H27: =CONVERT(205,"lbm","kg") -> 92.986436 | I27: kg | J27: Estimate Roskam
G28: per pax mass | H28: 105 | I28: kg | J28: Estimate EASA

Sheet V&V
B3: Class I weight estimation | K3: Wing
B4: ID | C4: Item | D4: Technique | E4: Justification | F4: Reference | G4: Result | H4: Confidence | K4: ID | L4: Item | M4: Technique | N4: Justification | O4: Reference | P4: Result | Q4: Confidence
B5: SST.C1W.1 | C5: MTOW | F5: CITE | G5: Pass | H5: High | L5: S
B6: SST.C1W.2 | C6: OEW | F6: CITE | G6: Pass | H6: High | L6: t/c
B7: SST.C1W.3 | C7: DFW | F7: CITE | G7: Pass | H7: High | L7: CL cruise
B12: T/W and W/S | K12: Propulsion
B13: ID | C13: Item | D13: Technique | E13: Justification | F13: Reference | G13: Result | H13: Confidence | K13: ID | L13: Item | M13: Technique | N13: Justification | O13: Reference | P13: Result | Q13: Confidence
B14: SST
B23: Fuselage | K23: Class II weight estimation
B24: ID | C24: Item | D24: Technique | E24: Justification | F24: Reference | G24: Result | H24: Confidence | K24: ID | L24: Item | M24: Technique | N24: Justification | O24: Reference | P24: Result | Q24: Confidence
B25: SST.FS.1 | C25: l_fuselage
B26: SST.FS.2 | C26: D_f_outer
B27: SST.FS.3 | C27: Vcc

Sheet Class 1 Weight est.
A1: Class I weight estimation | L1: Note | M1: #N/A means the specific aircraft does not meet the payload criteria
A2: NBR | B2: Aircraft | C2: Payload [N] | D2: MTOW [N] | E2: OEW [N] | F2: WL / WT | G2: Surface area [m2] | H2: Thrust [N] | I2: T/W | J2: W/S
A3: 1 | B3: =IF(ISNA(C3),DataBase!C3,DataBase!C3) -> E2-195 | C3: =IF(AND(DataBase!I3>=DataBase!$I$2*$N$6,DataBase!I3<=DataBase!$I$2*$M$6),DataBase!I3,NA()) *9.80665 -> 158377.4 | D3: =IF(ISNA(C3),NA(),DataBase!E3)*9.80665 -> 603108.97 | E3: =IF(ISNA(C3),NA(),DataBase!F3)*9.80665 -> 350097.4 | F3: =(E3+C3)/D3 -> 0.84308943 | G3: =IF(ISNA(C3),NA(),DataBase!L3) -> 103 | H3: =IF(ISNA(C3),NA(),DataBase!Q3)*1000 -> 105930 | I3: =2*(H3/D3) -> 0.3512798 | J3: =D3/G3 -> 5855.4269 | L3: Criteria
A4: 2 | B4: =IF(ISNA(C4),DataBase!C4,DataBase!C4) -> A319 | C4: =IF(AND(DataBase!I4>=DataBase!$I$2*$N$6,DataBase!I4<=DataBase!$I$2*$M$6),DataBase!I4,NA()) *9.80665 -> #N/A | D4: =IF(ISNA(C4),NA(),DataBase!E4)*9.80665 -> #N/A | E4: =IF(ISNA(C4),NA(),DataBase!F4)*9.80665 -> #N/A | F4: =(E4+C4)/D4 -> #N/A | G4: =IF(ISNA(C4),NA(),DataBase!L4) -> #N/A | H4: =IF(ISNA(C4),NA(),DataBase!Q4)*1000 -> #N/A | I4: =2*(H4/D4) -> #N/A | J4: =D4/G4 -> #N/A | L4: Name | M4: Value
A5: 3 | B5: =IF(ISNA(C5),DataBase!C5,DataBase!C5) -> A320 | C5: =IF(AND(DataBase!I5>=DataBase!$I$2*$N$6,DataBase!I5<=DataBase!$I$2*$M$6),DataBase!I5,NA()) *9.80665 -> 139744.76 | D5: =IF(ISNA(C5),NA(),DataBase!E5)*9.80665 -> 720788.77 | E5: =IF(ISNA(C5),NA(),DataBase!F5)*9.80665 -> 405112.71 | F5: =(E5+C5)/D5 -> 0.75591837 | G5: =IF(ISNA(C5),NA(),DataBase!L5) -> 122.4 | H5: =IF(ISNA(C5),NA(),DataBase!Q5)*1000 -> 120000 | I5: =2*(H5/D5) -> 0.33296856 | J5: =D5/G5 -> 5888.7972 | L5: Pax | M5: 150 | N5: - | P5: BWB numbers!!!! | AH5: Concept | AI5: MTOW [kg] | AJ5: OEW [kg] | AK5: Design Fuel Weight [kg]
A6: 4 | B6: =IF(ISNA(C6),DataBase!C6,DataBase!C6) -> A220-300 | C6: =IF(AND(DataBase!I6>=DataBase!$I$2*$N$6,DataBase!I6<=DataBase!$I$2*$M$6),DataBase!I6,NA()) *9.80665 -> 183384.35 | D6: =IF(ISNA(C6),NA(),DataBase!E6)*9.80665 -> 685484.83 | E6: =IF(ISNA(C6),NA(),DataBase!F6)*9.80665 -> 363630.58 | F6: =(E6+C6)/D6 -> 0.79799714 | G6: =IF(ISNA(C6),NA(),DataBase!L6) -> 112.3 | H6: =IF(ISNA(C6),NA(),DataBase!Q6)*1000 -> 103600 | I6: =2*(H6/D6) -> 0.30226781 | J6: =D6/G6 -> 6104.0502 | L6: Payload | M6: 1.2 | N6: 0.8 | AH6: CON | AI6: 66517 | AJ6: 36443 | AK6: 14324
A7: 5 | B7: =IF(ISNA(C7),DataBase!C7,DataBase!C7) -> MD-81 | C7: =IF(AND(DataBase!I7>=DataBase!$I$2*$N$6,DataBase!I7<=DataBase!$I$2*$M$6),DataBase!I7,NA()) *9.80665 -> 176058.79 | D7: =IF(ISNA(C7),NA(),DataBase!E7)*9.80665 -> 622722.27 | E7: =IF(ISNA(C7),NA(),DataBase!F7)*9.80665 -> 348822.54 | F7: =(E7+C7)/D7 -> 0.84288189 | G7: =IF(ISNA(C7),NA(),DataBase!L7) -> 112.3 | H7: =IF(ISNA(C7),NA(),DataBase!Q7)*1000 -> 85600 | I7: =2*(H7/D7) -> 0.27492191 | J7: =D7/G7 -> 5545.1672 | AH7: BOX | AI7: 72649 | AJ7: 47831 | AK7: 9068
A8: 6 | B8: =IF(ISNA(C8),DataBase!C8,DataBase!C8) -> MD-82 | C8: =IF(AND(DataBase!I8>=DataBase!$I$2*$N$6,DataBase!I8<=DataBase!$I$2*$M$6),DataBase!I8,NA()) *9.80665 -> 184384.63 | D8: =IF(ISNA(C8),NA(),DataBase!E8)*9.80665 -> 665008.55 | E8: =IF(ISNA(C8),NA(),DataBase!F8)*9.80665 -> 349410.94 | F8: =(E8+C8)/D8 -> 0.80268979 | G8: =IF(ISNA(C8),NA(),DataBase!L8) -> 112.3 | H8: =IF(ISNA(C8),NA(),DataBase!Q8)*1000 -> 92700 | I8: =2*(H8/D8) -> 0.27879341 | J8: =D8/G8 -> 5921.7146 | AH8: BWB | AI8: 49422 | AJ8: 27657 | AK8: 6015
A9: 7 | B9: =IF(ISNA(C9),DataBase!C9,DataBase!C9) -> MD-83 | C9: =IF(AND(DataBase!I9>=DataBase!$I$2*$N$6,DataBase!I9<=DataBase!$I$2*$M$6),DataBase!I9,NA()) *9.80665 -> 183590.29 | D9: =IF(ISNA(C9),NA(),DataBase!E9)*9.80665 -> 711766.66 | E9: =IF(ISNA(C9),NA(),DataBase!F9)*9.80665 -> 359119.52 | F9: =(E9+C9)/D9 -> 0.76248278 | G9: =IF(ISNA(C9),NA(),DataBase!L9) -> 112.3 | H9: =IF(ISNA(C9),NA(),DataBase!Q9)*1000 -> 96500 | I9: =2*(H9/D9) -> 0.27115628 | J9: =D9/G9 -> 6338.0824 | L9: Equation
A10: 8 | B10: =IF(ISNA(C10),DataBase!C10,DataBase!C10) -> MD-88 | C10: =IF(AND(DataBase!I10>=DataBase!$I$2*$N$6,DataBase!I10<=DataBase!$I$2*$M$6),DataBase!I10,NA()) *9.80665 -> 162790.39 | D10: =IF(ISNA(C10),NA(),DataBase!E10)*9.80665 -> 741186.61 | E10: =IF(ISNA(C10),NA(),DataBase!F10)*9.80665 -> 379909.62 | F10: =(E10+C10)/D10 -> 0.73220429 | G10: =IF(ISNA(C10),NA(),DataBase!L10) -> 112 | H10: =IF(ISNA(C10),NA(),DataBase!Q10)*1000 -> 93400 | I10: =2*(H10/D10) -> 0.2520283 | J10: =D10/G10 -> 6617.7376 | M10: a | N10: b
A11: 9 | B11: =IF(ISNA(C11),DataBase!C11,DataBase!C11) -> MD-90-30 | C11: =IF(AND(DataBase!I11>=DataBase!$I$2*$N$6,DataBase!I11<=DataBase!$I$2*$M$6),DataBase!I11,NA()) *9.80665 -> 170145.38 | D11: =IF(ISNA(C11),NA(),DataBase!E11)*9.80665 -> 693918.55 | E11: =IF(ISNA(C11),NA(),DataBase!F11)*9.80665 -> 386529.11 | F11: =(E11+C11)/D11 -> 0.80221877 | G11: =IF(ISNA(C11),NA(),DataBase!L11) -> 112.3 | H11: =IF(ISNA(C11),NA(),DataBase!Q11)*1000 -> 111200 | I11: =2*(H11/D11) -> 0.32049871 | J11: =D11/G11 -> 6179.1501 | L11: OEW | M11: {=SLOPE(IF(ISNUMBER(E3:E17),E3:E17),IF(ISNUMBER(D3:D17),D3:D17))} -> 0.51396471 | N11: {=INTERCEPT(IF(ISNUMBER(E3:E17),E3:E17),IF(ISNUMBER(D3:D17),D3:D17))} -> 22121.455
A12: 10 | B12: =IF(ISNA(C12),DataBase!C12,DataBase!C12) -> DC 9-50 | C12: =IF(AND(DataBase!I12>=DataBase!$I$2*$N$6,DataBase!I12<=DataBase!$I$2*$M$6),DataBase!I12,NA()) *9.80665 -> 149698.51 | D12: =IF(ISNA(C12),NA(),DataBase!E12)*9.80665 -> 533677.89 | E12: =IF(ISNA(C12),NA(),DataBase!F12)*9.80665 -> 287334.84 | F12: =(E12+C12)/D12 -> 0.81890849 | G12: =IF(ISNA(C12),NA(),DataBase!L12) -> 92.97 | H12: =IF(ISNA(C12),NA(),DataBase!Q12)*1000 -> 68900 | I12: =2*(H12/D12) -> 0.25820818 | J12: =D12/G12 -> 5740.3237 | L12: MTOW | M12: {=SLOPE(IF(ISNUMBER(D3:D17),D3:D17),IF(ISNUMBER(C3:C17),C3:C17))} -> 4.5879032 | N12: {=INTERCEPT(IF(ISNUMBER(D3:D17),D3:D17),IF(ISNUMBER(C3:C17),C3:C17))} -> -67986.463
A13: 11 | B13: =IF(ISNA(C13),DataBase!C13,DataBase!C13) -> 204–300 | C13: =IF(AND(DataBase!I13>=DataBase!$I$2*$N$6,DataBase!I13<=DataBase!$I$2*$M$6),DataBase!I13,NA()) *9.80665 -> 176519.7 | D13: =IF(ISNA(C13),NA(),DataBase!E13)*9.80665 -> 1049311.6 | E13: =IF(ISNA(C13),NA(),DataBase!F13)*9.80665 -> 563490.11 | F13: =(E13+C13)/D13 -> 0.70523364 | G13: =IF(ISNA(C13),NA(),DataBase!L13) -> 184.2 | H13: =IF(ISNA(C13),NA(),DataBase!Q13)*1000 -> 158200 | I13: =2*(H13/D13) -> 0.30153104 | J13: =D13/G13 -> 5696.5882
A14: 12 | B14: =IF(ISNA(C14),DataBase!C14,DataBase!C14) -> Tu-154M | C14: =IF(AND(DataBase!I14>=DataBase!$I$2*$N$6,DataBase!I14<=DataBase!$I$2*$M$6),DataBase!I14,NA()) *9.80665 -> 176519.7 | D14: =IF(ISNA(C14),NA(),DataBase!E14)*9.80665 -> 980665 | E14: =IF(ISNA(C14),NA(),DataBase!F14)*9.80665 -> 542307.74 | F14: =(E14+C14)/D14 -> 0.733 | G14: =IF(ISNA(C14),NA(),DataBase!L14) -> 201.45 | H14: =IF(ISNA(C14),NA(),DataBase!Q14)*1000 -> 104000 | I14: =2*(H14/D14) -> 0.21210097 | J14: =D14/G14 -> 4868.0318 | L14: Final values | P14: Final values
A15: 13 | B15: =IF(ISNA(C15),DataBase!C15,DataBase!C15) -> 737-700 | C15: =IF(AND(DataBase!I15>=DataBase!$I$2*$N$6,DataBase!I15<=DataBase!$I$2*$M$6),DataBase!I15,NA()) *9.80665 -> #N/A | D15: =IF(ISNA(C15),NA(),DataBase!E15)*9.80665 -> #N/A | E15: =IF(ISNA(C15),NA(),DataBase!F15)*9.80665 -> #N/A | F15: =(E15+C15)/D15 -> #N/A | G15: =IF(ISNA(C15),NA(),DataBase!L15) -> #N/A | H15: =IF(ISNA(C15),NA(),DataBase!Q15)*1000 -> #N/A | I15: =2*(H15/D15) -> #N/A | J15: =D15/G15 -> #N/A | L15: Name | M15: Value | N15: Unit | P15: Name | Q15: Value | R15: Unit
A16: 14 | B16: =IF(ISNA(C16),DataBase!C16,DataBase!C16) -> 737-300 | C16: =IF(AND(DataBase!I16>=DataBase!$I$2*$N$6,DataBase!I16<=DataBase!$I$2*$M$6),DataBase!I16,NA()) *9.80665 -> 157200.6 | D16: =IF(ISNA(C16),NA(),DataBase!E16)*9.80665 -> 553781.53 | E16: =IF(ISNA(C16),NA(),DataBase!F16)*9.80665 -> 312528.13 | F16: =(E16+C16)/D16 -> 0.84822029 | G16: =IF(ISNA(C16),NA(),DataBase!L16) -> 91.04 | H16: =IF(ISNA(C16),NA(),DataBase!Q16)*1000 -> 100000 | I16: =2*(H16/D16) -> 0.36115325 | J16: =D16/G16 -> 6082.8375 | L16: Design Payload Weight | M16: =DataBase!I2*9.80665 -> 154454.74 | N16: N | P16: Design Payload Weight | Q16: =M16/9.80665 -> 15750 | R16: kg
A17: 15 | B17: =IF(ISNA(C17),DataBase!C17,DataBase!C17) -> 737-500 | C17: =IF(AND(DataBase!I17>=DataBase!$I$2*$N$6,DataBase!I17<=DataBase!$I$2*$M$6),DataBase!I17,NA()) *9.80665 -> 152297.27 | D17: =IF(ISNA(C17),NA(),DataBase!E17)*9.80665 -> 513770.39 | E17: =IF(ISNA(C17),NA(),DataBase!F17)*9.80665 -> 303613.88 | F17: =(E17+C17)/D17 -> 0.88738309 | G17: =IF(ISNA(C17),NA(),DataBase!L17) -> 91 | H17: =IF(ISNA(C17),NA(),DataBase!Q17)*1000 -> 100000 | I17: =2*(H17/D17) -> 0.38927895 | J17: =D17/G17 -> 5645.8285 | L17: MTOW | M17: 794243.86 | N17: N | P17: MTOW | Q17: =M17/9.80665 -> 80990.334 | R17: kg
L18: OEW | M18: 627484.5 | N18: N | P18: OEW | Q18: =M18/9.80665 -> 63985.612 | R18: kg
L19: Design Fuel Weight | M19: 12304.618 | N19: N | P19: Design Fuel Weight | Q19: =M19/9.80665 -> 1254.7218 | R19: kg
B21: Weight fractions | H21: Preliminary aerodynamic data
B22: Name | C22: Sign | D22: Value | E22: Unit | F22: Note | H22: Name | I22: Sign | J22: Value | K22: Unit | L22: Note
A23: M1 | B23: Warm-up | C23: W1 / Wto | D23: 0.99 | E23: - | F23: Table | H23: Generic | P23: From DataBase
A24: M2 | B24: Taxi | C24: W2 / W1 | D24: 0.99 | E24: - | F24: Table | H24: CD0 | I24: CD0 | J24: =J27*J28 -> 0.009 | K24: - | L24: - | P24: Name | Q24: Sign | R24: Value | S24: Unit | T24: Note
A25: M3 | B25: Take-off | C25: W3 / W2 | D25: 0.995 | E25: - | F25: Table | H25: Aspect ratio | I25: A | J25: 7 | K25: - | L25: Assumed | P25: Design Payload Weight | Q25: Wpl design | R25: =DataBase!I2 -> 15750 | S25: kg | T25: Req. | AC25: Yes, I know, it doesn’t look right…
A26: M4 | B26: Climb 1 | C26: W4 / W3 | D26: 0.98 | E26: - | F26: Table | H26: Oswald eff. | I26: e | J26: 1 | K26: - | L26: Assumed | P26: Design Range | Q26: Rdesign | R26: =DataBase!H2 -> 3700 | S26: km | T26: Req.
A27: M5 | B27: Cruise 1 | C27: W5 / W4 | D27: =(EXP((DataBase!H2*'Class 1 Weight est.'!J34*1000*9.80665/'Class 1 Weight est.'!J35)/'Class 1 Weight est.'!J31))^-1 -> 0.95704302 | E27: - | F27: - | H27: Skin friction | I27: Cfe | J27: 0.003 | K27: - | L27: Assumed | AF27: max | AG27: mtow | AH27: =Q17 -> 80990.334 | AJ27: =AH27 -> 80990.334
A28: M6 | B28: Descent 1 | C28: W6 / W5 | D28: 0.99 | E28: - | F28: Table | H28: Wing area ratio | I28: Swet / S | J28: 3 | K28: - | L28: Assumed | AF28: max | AG28: fuel | AH28: =AH27-AH29 -> 62090.334 | AJ28: =AJ27-AJ29 -> 65240.334
A29: M7 | B29: Climb 2 | C29: W7 / W6 | D29: 1 | E29: - | F29: Not inlcuded | H29: Cruise | P29: Payload - Range diagram | AF29: max | AG29: pld | AH29: =Q16*1.2 -> 18900 | AJ29: =R25 -> 15750
A30: M8 | B30: Cruise 2 | C30: W8 / W7 | D30: 1 | E30: - | F30: Not included | H30: Design Range | I30: Rdesign | J30: =DataBase!H2 -> 3700 | K30: km | L30: Requirement | P30: Name | Q30: Sign | R30: Value | S30: Unit | T30: Note
A31: M9 | B31: Loiter | C31: W9 / W8 | D31: =(EXP(J39*9.80665*J43/J42))^-1 -> 0.99303287 | E31: - | F31: - | H31: Cruise L/D | I31: (L/D) cruise | J31: =J32/J33 -> 21.404414 | K31: - | L31: - | P31: Design Fuel Weight | Q31: WF,des | R31: =Q17-R25-Q18 -> 1254.7218 | S31: kg | T31: -
A32: M10 | B32: Descent 2 | C32: W10 / W9 | D32: 1 | E32: - | F32: Not included | H32: Cruise CL | I32: CL cruise | J32: =SQRT((J24*PI()*J25*J26)/(3)) -> 0.25685297 | K32: - | L32: - | P32: Max Payload Weight | Q32: Wpl,max | R32: =Q16*1.1 -> 17325 | S32: kg | T32: Random value
A33: M11 | B33: Land, taxi, shut-down | C33: Wfinal / W10 | D33: =0.992 -> 0.992 | E33: - | F33: - | H33: Cruise CD | I33: CD cruise | J33: =(4/3)*J24 -> 0.012 | K33: - | L33: - | Q33: W4, harmonic | R33: =Q17*PRODUCT(D23:D26) -> 77402.099 | S33: - | T33: -
B34: Fuel fraction | C34: Mff | D34: =PRODUCT(D23:D33) -> 0.8919931 | E34: - | F34: - | H34: Specific fuel consmp. | I34: cj cruise | J34: =6.1183*10^-6 -> 6.1183e-06 | K34: kg/N/s | L34: Assumed | Q34: W5, harmonic | R34: =(Q18+R32)/(PRODUCT(D28:D33)) -> 83375.172 | S34: - | T34: -
B35: Reserved fuel | C35: Mres | D35: 0.05 | E35: - | F35: Assumed | H35: Cruise speed | I35: Vcruise | J35: 236.22 | K35: m/s | L35: Nasa calculator | P35: Harmonic Range | Q35: Rharmonic | R35: =((J35)/(9.80665*J34))*J31*LN(R33/R34)*10^-3 -> -6264.287 | S35: km | T35: -
B36: Trapped fuel and oil | C36: Mtfo | D36: =0 -> 0 | E36: - | F36: Not used | H36: Cruise altitude | I36: hcruise | J36: =CONVERT(36000,"ft","m") -> 10972.8 | K36: m | L36: Estimate | P36: Max Fuel Weight | Q36: WF,max | R36: =Q19+Q16*0.7 -> 12279.722 | S36: kg | T36: Random value
H37: Cruise Mach | I37: Mcruise | J37: 0.8 | K37: - | L37: Estimate | Q37: W4, ferry | R37: =(Q18+R36+0)*PRODUCT(D23:D26) -> 72886.437 | S37: - | T37: -
B38: FactorStartCruise | D38: =PRODUCT(D23:D26) -> 0.95569551 | E38: =D38*$M$17 -> 759055.29 | F38: N | H38: Loiter | Q38: W5, ferry | R38: =(Q18+0)/(PRODUCT(D28:D33)) -> 65610.272 | S38: - | T38: -
B39: FactofEndCruise | D39: =PRODUCT(D23:D27) -> 0.91464171 | E39: =D39*$M$17 -> 726448.57 | F39: N | H39: Loiter time | I39: E | J39: 3600 | K39: sec | L39: Assumed | P39: Ferry Range | Q39: Rferry | R39: =((J35)/(9.80665*J34))*J31*LN(R37/R38)*10^-3 -> 8862.6112 | S39: km | T39: - | X39: Conventional | AA39: Box | AD39: BWB
D40: Cruise Weight | E40: =AVERAGE(E38:E39) -> 742751.93 | F40: N | H40: Loiter CL | I40: CL loiter | J40: =SQRT(PI()*J25*J26*J24) -> 0.44488239 | K40: - | L40: - | X40: Range [km] | Y40: Payload weight [kg] | AA40: Range [km] | AB40: Payload weight [kg] | AD40: Range [km] | AE40: Payload weight [kg]
H41: Loiter CD | I41: CD loiter | J41: =2*J24 -> 0.018 | K41: - | L41: - | X41: 0 | Y41: =R32 -> 17325 | AA41: 0 | AB41: ='[1]Class 1 Weight est.'!$R$32 -> 18900 | AD41: 0 | AE41: ='[2]Class 1 Weight est.'!$R$32 -> 16537.5
...

Sheet TW and WS
A1: ADSEE-I DATA (Transport Jet)
A2: CLmax Clean | C2: CLmax Take-off | E2: CLmax Land | Q2: Calculations
A3: Min | B3: Max | C3: Min | D3: Max | E3: Min | F3: Max | Q3: Name | R3: Sign | S3: Values | T3: Unit | U3: Notes
A4: 1.7349276 | B4: 1.7349276 | C4: 1.7349276 | D4: 1.7349276 | E4: 1.7349276 | F4: 1.7349276 | Q4: Landing Stall Speed | R4: Vs,land | S4: =SQRT(C18/0.5847) -> 48.932507 | T4: m/s | U4: CS25
I5: Oswald Efficiency | M5: CD0 | Q5: Stall Speed | R5: Vstall | S5: =C22/1.2 -> 68.431501 | T5: m/s | U5: Formula from the internet
A6: CLmax Clean | C6: Aspect Ratio | I6: Clean | J6: Take-off | K6: Landing | M6: Clean | N6: Take-off | O6: Landing | Q6: Take Off Speed | R6: VTO | S6: =1.1*S5 -> 75.274651 | T6: m/s | U6: Raymer's method
A7: 1.7349276 | C7: 9.1323969 | I7: 0.7 | J7: =I7 -> 0.7 | K7: =I7 -> 0.7 | M7: 0.00692428 | N7: 0.00692428 | O7: 0.00692428 | Q7: Take Off CL | R7: CLTO | T7: - | U7: Raymer's method
A8: 62 | J8: We consider climb as well | N8: We consider climb as well | Q8: Wing loading in Take-Off | R8: (W/S) TO | S8: =(E7*B32*S4^2)/(2*(('Class 1 Weight est.'!Q18+'Class 1 Weight est.'!Q16)/('Class 1 Weight est.'!Q17))) -> 0 | T8: N/m2 | U8: CS / JAR / FAR 25
Q9: Stall Wing Loading | R9: W/S | S9: =0.5*B32*S5^2*A7 -> 4976.22 | T9: N/m2 | U9: General
Q10: Thrust to Weight Ratio | R10: TTO/W | T10: - | U10: ADSEE-I
Q11: Stall Wing Loading - Landing | R11: W/S landing | T11: N/m2 | U11: General
A12: Design Aircraft Data | H12: TOP | I12: =(CONVERT(C17,"m","ft")/37.5)*4.88242764*9.80665 -> 8377.9981 | J12: Raymer
A13: Name | C13: Data | D13: Unit | E13: SI
A14: Payloadmax | C14: ='Class 1 Weight est.'!Q16 -> 15750 | D14: kg | E14: =C14*B29 -> 154454.74 | F14: N | H14: Final values
A15: Cruise Mach number | C15: ='Class 1 Weight est.'!J37 -> 0.8 | D15: - | E15: =C15 -> 0.8 | F15: - | H15: Sign / Name | I15: Value | J15: Unit
A16: Cruise altitude | C16: =CONVERT('Class 1 Weight est.'!J36,"m","ft") -> 36000 | D16: ft | E16: =CONVERT(C16,"ft","m") -> 10972.8 | F16: m | H16: T/W | I16: 0.215 | J16: - | L16: C values | S16: W/S values
A17: Take-off distance sTO | C17: =DataBase!J2 -> 2000 | D17: m | E17: =C17 -> 2000 | F17: m | H17: W/S | I17: 2250 | J17: N/m2 | L17: Name | M17: Sign | N17: Value | O17: Unit | P17: Notes | S17: Name | T17: Sign | U17: Value | V17: Unit | W17: Notes
A18: Landing distance sland | C18: =DataBase!K2 -> 1400 | D18: m | E18: =C18 -> 1400 | F18: m | H18: Wing surface | I18: =I17^-1*'Class 1 Weight est.'!M17 -> 352.99727 | J18: m2 | L18: CL max in landing | M18: CLmax land | N18: =(I17*2*(('Class 1 Weight est.'!M18+'Class 1 Weight est.'!M16)/('Class 1 Weight est.'!M17)))/(B32*S4^2) -> 1.5104301 | O18: - | P18: Graph | S18: Wing loading start of cruise | T18: W/S start cruise | U18: =PRODUCT('Class 1 Weight est.'!D23:D26)*'Class 1 Weight est.'!M17/'Wing Design'!E8 -> 2150.3149 | V18: N/m2 | W18: -
A19: Landing Field Length sLFL | C19: =C18*(1/0.6) -> 2333.3333 | D19: m | E19: =C19 -> 2333.3333 | F19: m | H19: Thrust | I19: =I16*'Class 1 Weight est.'!M17 -> 170762.43 | J19: N | L19: CL max in TO | M19: CLmax TO | N19: =((I16*(I12/I17))^-1)*1.1^2 -> 1.5114339 | O19: - | P19: Graph | S19: Wing loading end of cruise | T19: W/S end cruise | U19: =PRODUCT('Class 1 Weight est.'!D23:D27)*'Class 1 Weight est.'!M17/'Wing Design'!E8 -> 2057.9439 | V19: N/m2 | W19: -
A20: Design Mission Range | C20: ='Class 1 Weight est.'!J30 -> 3700 | D20: km | E20: =C20*1000 -> 3700000 | F20: m | L20: CL max in clean | M20: CLmax clean | N20: =A7 -> 1.7349276 | O20: - | P20: Graph
A21: with Payload | C21: ='Class 1 Weight est.'!Q16 -> 15750 | D21: kg | E21: =C21*B29 -> 154454.74 | F21: N
A22: Approach Speed VAPP | C22: =1.7*SQRT(C19) -> 82.117802 | D22: m/s | E22: =C22 -> 82.117802 | F22: m/s
A23: Ferry Range | C23: ='Class 1 Weight est.'!R39 -> 8862.6112 | D23: km | E23: =C23*1000 -> 8862611.2 | F23: m
A25: Constants | D25: Data @ Cruise | I25: Stall for Landing | O25: Take-off
A26: Pressure @ Sea Level | B26: 101325 | C26: Pa | D26: Pressure | E26: =E27*E29*B31 -> 22730.294 | F26: Pa | I26: W/S | J26: =(J28*$B$32*$S$4^2)/(2*(('Class 1 Weight est.'!$Q$18+'Class 1 Weight est.'!$Q$16)/('Class 1 Weight est.'!$Q$17))) -> 2584.4209 | K26: =(K28*$B$32*$S$4^2)/(2*(('Class 1 Weight est.'!$Q$18+'Class 1 Weight est.'!$Q$16)/('Class 1 Weight est.'!$Q$17))) -> 2584.4209 | L26: =(L28*$B$32*$S$4^2)/(2*(('Class 1 Weight est.'!$Q$18+'Class 1 Weight est.'!$Q$16)/('Class 1 Weight est.'!$Q$17))) -> 2584.4209 | O26: CLmax Take-off
A27: a (gradient) | B27: =-6.5/1000 -> -0.0065 | C27: K/m | D27: Temp | E27: =B28+B27*E16 -> 216.8268 | F27: K | J27: CLmax Land | O27: =C4 -> 1.7349276 | Q27: =AVERAGE(C4:D4) -> 1.7349276 | S27: =D4 -> 1.7349276 | W27: Cruise | AC27: Climb rate | AN27: Climb gradient | AX27: Manouvering
A28: Temp sea level | B28: 288.15 | C28: K | D28: g | E28: 9.80665 | F28: m/s2 | I28: TO | J28: =F4 -> 1.7349276 | K28: =AVERAGE(E4:F4) -> 1.7349276 | L28: =E4 -> 1.7349276 | O28: =$O$25&" "&O27 -> Take-off 1.73492756 | Q28: =$O$25&" "&Q27 -> Take-off 1.73492756 | S28: =$O$25&" "&S27 -> Take-off 1.73492756 | X28: =C7 -> 9.1323969 | Y28: =X28+3 -> 12.132397 | Z28: =Y28+3 -> 15.132397 | AD28: =C7 -> 9.1323969 | AF28: =AD28+3 -> 12.132397 | AH28: =AF28+3 -> 15.132397 | AJ28: c | AO28: =C7 -> 9.1323969 | AQ28: =AO28+3 -> 12.132397 | AS28: =AQ28+3 -> 15.132397 | AY28: =C7 -> 9.1323969 | BA28: =AY28+3 -> 12.132397 | BC28: =BA28+3 -> 15.132397
A29: g0 | B29: 9.80665 | C29: m/s2 | D29: Density (ρ) cruise | E29: =(B32*(E27/B28)^((-B29/(B27*B31))-1)) -> 0.36519299 | F29: kg/m3 | I29: 1.6 | J29: =(($I$12/$J$26)*$I29*1)^-1 -> 0.19279821 | K29: =(($I$12/$K$26)*$I29*1)^-1 -> 0.19279821 | L29: =(($I$12/$L$26)*$I29*1)^-1 -> 0.19279821 | O29: W/S | P29: T/W | Q29: W/S | R29: T/W | S29: W/S | T29: T/W | X29: =$W$27&" "&X28 -> Cruise 9.13239686 | Y29: =$W$27&" "&Y28 -> Cruise 12.13239686 | Z29: =$W$27&" "&Z28 -> Cruise 15.13239686 | AC29: CL | AD29: =SQRT(3*$N$7*PI()*AD28*$J$7) -> 0.64589851 | AF29: =SQRT(3*$N$7*PI()*AF28*$J$7) -> 0.74446657 | AH29: =SQRT(3*$N$7*PI()*AH28*$J$7) -> 0.83143012 | AJ29: =12.7 -> 12.7 | AK29: A320
A30: Radius of Earth | B30: 6378.136 | C30: km | D30: Speed of Sound | E30: =SQRT(1.4*E27*B31) -> 295.1925 | F30: m/s | I30: This 1.6 TO value is just a placeholder. | O30: 100 | P30: =(($I$12/O30)*($O$27/1.1^2)*1)^-1 -> 0.0083246075 | Q30: 100 | R30: =(($I$12/Q30)*($Q$27/1.1^2)*1)^-1 -> 0.0083246075 | S30: 100 | T30: =(($I$12/S30)*($S$27/1.1^2)*1)^-1 -> 0.0083246075 | W30: 100 | X30: =((($M$7*0.5*$E$29*$E$31^2)/($E$32*W30))+($E$32*W30)*(1/(PI()*$X$28*$I$7*0.5*$E$29*$E$31^2)))*($B$32/$E$29)^(3/4)*($E$32/$E$33) -> 3.4977136 | Y30: =((($M$7*0.5*$E$29*$E$31^2)/(W30*$E$32))+(W30*$E$32)*(1/(PI()*$Y$28*$I$7*0.5*$E$29*$E$31^2)))*($B$32/$E$29)^(3/4)*($E$32/$E$33) -> 3.4971436 | Z30: =((($M$7*0.5*$E$29*$E$31^2)/(W30*$E$32))+(W30*$E$32)*(1/(PI()*$Z$28*$I$7*0.5*$E$29*$E$31^2)))*($B$32/$E$29)^(3/4)*($E$32/$E$33) -> 3.4967996 | AC30: CD | AD30: =4*$N$7 -> 0.02769712 | AF30: =4*$N$7 -> 0.02769712 | AH30: =4*$N$7 -> 0.02769712 | AN30: c/V | AO30: =ATAN(AR30/100) -> 0.023995394 | AQ30: Gradient [%] | AR30: 2.4 | AS30: CS25 | AX30: Max load factor | AY30: 2.5
A31: R | B31: 287.058 | C31: - | D31: Cruise Velocity | E31: =E30*C15 -> 236.154 | F31: m/s | O31: 200 | P31: =(($I$12/O31)*($O$27/1.1^2)*1)^-1 -> 0.016649215 | Q31: 200 | R31: =(($I$12/Q31)*($Q$27/1.1^2)*1)^-1 -> 0.016649215 | S31: 200 | T31: =(($I$12/S31)*($S$27/1.1^2)*1)^-1 -> 0.016649215 | W31: 200 | X31: =((($M$7*0.5*$E$29*$E$31^2)/($E$32*W31))+($E$32*W31)*(1/(PI()*$X$28*$I$7*0.5*$E$29*$E$31^2)))*($B$32/$E$29)^(3/4)*($E$32/$E$33) -> 1.7523146 | Y31: =((($M$7*0.5*$E$29*$E$31^2)/(W31*$E$32))+(W31*$E$32)*(1/(PI()*$Y$28*$I$7*0.5*$E$29*$E$31^2)))*($B$32/$E$29)^(3/4)*($E$32/$E$33) -> 1.7511746 | Z31: =((($M$7*0.5*$E$29*$E$31^2)/(W31*$E$32))+(W31*$E$32)*(1/(PI()*$Z$28*$I$7*0.5*$E$29*$E$31^2)))*($B$32/$E$29)^(3/4)*($E$32/$E$33) -> 1.7504866 | AD31: =$AC$27&" "&AD28 -> Climb rate 9.13239686 | AF31: =$AC$27&" "&AF28 -> Climb rate 12.13239686 | AH31: =$AC$27&" "&AH28 -> Climb rate 15.13239686 | AQ31: Gradient [deg] | AR31: =AR30*0.5718 -> 1.37232
A32: Density @ Sea Level ρ0 | B32: 1.225 | C32: kg/m3 | D32: Weight fraction | E32: =(PRODUCT('Class 1 Weight est.'!D23:D25)*'Class 1 Weight est.'!M17)/('Class 1 Weight est.'!M17) -> 0.9751995 | F32: - | I32: Name | J32: =$I$25&" "&J28 -> Stall for Landing 1.73492756 | K32: =$I$25&" "&K28 -> Stall for Landing 1.73492756 | L32: =$I$25&" "&L28 -> Stall for Landing 1.73492756 | O32: 300 | P32: =(($I$12/O32)*($O$27/1.1^2)*1)^-1 -> 0.024973823 | Q32: 300 | R32: =(($I$12/Q32)*($Q$27/1.1^2)*1)^-1 -> 0.024973823 | S32: 300 | T32: =(($I$12/S32)*($S$27/1.1^2)*1)^-1 -> 0.024973823 | W32: 300 | X32: =((($M$7*0.5*$E$29*$E$31^2)/($E$32*W32))+($E$32*W32)*(1/(PI()*$X$28*$I$7*0.5*$E$29*$E$31^2)))*($B$32/$E$29)^(3/4)*($E$32/$E$33) -> 1.1720518 | Y32: =((($M$7*0.5*$E$29*$E$31^2)/(W32*$E$32))+(W32*$E$32)*(1/(PI()*$Y$28*$I$7*0.5*$E$29*$E$31^2)))*($B$32/$E$29)^(3/4)*($E$32/$E$33) -> 1.1703417 | Z32: =((($M$7*0.5*$E$29*$E$31^2)/(W32*$E$32))+(W32*$E$32)*(1/(PI()*$Z$28*$I$7*0.5*$E$29*$E$31^2)))*($B$32/$E$29)^(3/4)*($E$32/$E$33) -> 1.1693097 | AO32: =$AN$27&" "&AO28 -> Climb gradient 9.13239686 | AQ32: =$AN$27&" "&AQ28 -> Climb gradient 12.13239686 | AS32: =$AN$27&" "&AS28 -> Climb gradient 15.13239686 | AY32: =$AX$27&" "&AY28 -> Manouvering 9.13239686 | BA32: =$AX$27&" "&BA28 -> Manouvering 12.13239686 | BC32: =$AX$27&" "&BC28 -> Manouvering 15.13239686
D33: Thrust setting | E33: 0.5 | F33: - | O33: 400 | P33: =(($I$12/O33)*($O$27/1.1^2)*1)^-1 -> 0.03329843 | Q33: 400 | R33: =(($I$12/Q33)*($Q$27/1.1^2)*1)^-1 -> 0.03329843 | S33: 400 | T33: =(($I$12/S33)*($S$27/1.1^2)*1)^-1 -> 0.03329843 | W33: 400 | X33: =((($M$7*0.5*$E$29*$E$31^2)/($E$32*W33))+($E$32*W33)*(1/(PI()*$X$28*$I$7*0.5*$E$29*$E$31^2)))*($B$32/$E$29)^(3/4)*($E$32/$E$33) -> 0.88307295 | Y33: =((($M$7*0.5*$E$29*$E$31^2)/(W33*$E$32))+(W33*$E$32)*(1/(PI()*$Y$28*$I$7*0.5*$E$29*$E$31^2)))*($B$32/$E$29)^(3/4)*($E$32/$E$33) -> 0.88079289 | Z33: =((($M$7*0.5*$E$29*$E$31^2)/(W33*$E$32))+(W33*$E$32)*(1/(PI()*$Z$28*$I$7*0.5*$E$29*$E$31^2)))*($B$32/$E$29)^(3/4)*($E$32/$E$33) -> 0.87941687 | AD33: T/W | AE33: W/S | AF33: T/W | AG33: W/S | AH33: T/W | AI33: W/S | AO33: T/W | AP33: W/S | AQ33: T/W | AR33: W/S | AS33: T/W | AT33: W/S | AY33: T/W | AZ33: W/S | BA33: T/W | BB33: W/S | BC33: T/W | BD33: W/S
O34: 500 | P34: =(($I$12/O34)*($O$27/1.1^2)*1)^-1 -> 0.041623038 | Q34: 500 | R34: =(($I$12/Q34)*($Q$27/1.1^2)*1)^-1 -> 0.041623038 | S34: 500 | T34: =(($I$12/S34)*($S$27/1.1^2)*1)^-1 -> 0.041623038 | W34: 500 | X34: =((($M$7*0.5*$E$29*$E$31^2)/($E$32*W34))+($E$32*W34)*(1/(PI()*$X$28*$I$7*0.5*$E$29*$E$31^2)))*($B$32/$E$29)^(3/4)*($E$32/$E$33) -> 0.71060775 | Y34: =((($M$7*0.5*$E$29*$E$31^2)/(W34*$E$32))+(W34*$E$32)*(1/(PI()*$Y$28*$I$7*0.5*$E$29*$E$31^2)))*($B$32/$E$29)^(3/4)*($E$32/$E$33) -> 0.70775767 | Z34: =((($M$7*0.5*$E$29*$E$31^2)/(W34*$E$32))+(W34*$E$32)*(1/(PI()*$Z$28*$I$7*0.5*$E$29*$E$31^2)))*($B$32/$E$29)^(3/4)*($E$32/$E$33) -> 0.70603765 | AD34: =(($AJ$29)/(SQRT(AE34)*SQRT((2/$B$32)*(1/$AD$29))))+($AD$30/$AD$29) -> 0.8416831 | AE34: 100 | AF34: =(($AJ$29)/(SQRT(AG34)*SQRT((2/$B$32)*(1/$AF$29))))+($AF$30/$AF$29) -> 0.89479331 | AG34: 100 | AH34: =(($AJ$29)/(SQRT(AI34)*SQRT((2/$B$32)*(1/$AH$29))))+($AH$30/$AH$29) -> 0.93960775 | AI34: 100 | AO34: =(($AO$30)+2*SQRT(($N$7)/(PI()*$AO$28*$J$7)))*2 -> 0.12226379 | AP34: 0 | AQ34: =(($AO$30)+2*SQRT(($N$7)/(PI()*$AQ$28*$J$7)))*2 -> 0.11242997 | AR34: 0 | AS34: =(($AO$30)+2*SQRT(($N$7)/(PI()*$AS$28*$J$7)))*2 -> 0.10568995 | AT34: 0 | AY34: =(($M$7*0.5*$B$32*$E$31^2)/(AZ34))+AZ34*($AY$30^2/(PI()*$AY$28*$I$7*0.5*$B$32*$E$31^2)) -> #DIV/0! | AZ34: 0 | BA34: =(($M$7*0.5*$B$32*$E$31^2)/(BB34))+BB34*(($AY$30^2)/(PI()*$BA$28*$I$7*0.5*$B$32*$E$31^2)) -> #DIV/0! | BB34: 0 | BC34: =(($M$7*0.5*$B$32*$E$31^2)/(BD34))+BD34*(($AY$30^2)/(PI()*$BC$28*$I$7*0.5*$B$32*$E$31^2)) -> #DIV/0! | BD34: 0
O35: 600 | P35: =(($I$12/O35)*($O$27/1.1^2)*1)^-1 -> 0.049947645 | Q35: 600 | R35: =(($I$12/Q35)*($Q$27/1.1^2)*1)^-1 -> 0.049947645 | S35: 600 | T35: =(($I$12/S35)*($S$27/1.1^2)*1)^-1 -> 0.049947645 | W35: 600 | X35: =((($M$7*0.5*$E$29*$E$31^2)/($E$32*W35))+($E$32*W35)*(1/(PI()*$X$28*$I$7*0.5*$E$29*$E$31^2)))*($B$32/$E$29)^(3/4)*($E$32/$E$33) -> 0.59639935 | Y35: =((($M$7*0.5*$E$29*$E$31^2)/(W35*$E$32))+(W35*$E$32)*(1/(PI()*$Y$28*$I$7*0.5*$E$29*$E$31^2)))*($B$32/$E$29)^(3/4)*($E$32/$E$33) -> 0.59297926 | Z35: =((($M$7*0.5*$E$29*$E$31^2)/(W35*$E$32))+(W35*$E$32)*(1/(PI()*$Z$28*$I$7*0.5*$E$29*$E$31^2)))*($B$32/$E$29)^(3/4)*($E$32/$E$33) -> 0.59091524 | AD35: =(($AJ$29)/(SQRT(AE35)*SQRT((2/$B$32)*(1/$AD$29))))+($AD$30/$AD$29) -> 0.60771954 | AE35: 200 | AF35: =(($AJ$29)/(SQRT(AG35)*SQRT((2/$B$32)*(1/$AF$29))))+($AF$30/$AF$29) -> 0.64361121 | AG35: 200 | AH35: =(($AJ$29)/(SQRT(AI35)*SQRT((2/$B$32)*(1/$AH$29))))+($AH$30/$AH$29) -> 0.67416006 | AI35: 200 | AO35: =(($AO$30)+2*SQRT(($N$7)/(PI()*$AO$28*$J$7)))*2 -> 0.12226379 | AP35: 100 | AQ35: =(($AO$30)+2*SQRT(($N$7)/(PI()*$AQ$28*$J$7)))*2 -> 0.11242997 | AR35: 100 | AS35: =(($AO$30)+2*SQRT(($N$7)/(PI()*$AS$28*$J$7)))*2 -> 0.10568995 | AT35: 100 | AY35: =(($M$7*0.5*$B$32*$E$31^2)/(AZ35))+AZ35*($AY$30^2/(PI()*$AY$28*$I$7*0.5*$B$32*$E$31^2)) -> 2.36613 | AZ35: 100 | BA35: =(($M$7*0.5*$B$32*$E$31^2)/(BB35))+BB35*(($AY$30^2)/(PI()*$BA$28*$I$7*0.5*$B$32*$E$31^2)) -> 2.3659047 | BB35: 100 | BC35: =(($M$7*0.5*$B$32*$E$31^2)/(BD35))+BD35*(($AY$30^2)/(PI()*$BC$28*$I$7*0.5*$B$32*$E$31^2)) -> 2.3657687 | BD35: 100
O36: 700 | P36: =(($I$12/O36)*($O$27/1.1^2)*1)^-1 -> 0.058272253 | Q36: 700 | R36: =(($I$12/Q36)*($Q$27/1.1^2)*1)^-1 -> 0.058272253 | S36: 700 | T36: =(($I$12/S36)*($S$27/1.1^2)*1)^-1 -> 0.058272253 | W36: 700 | X36: =((($M$7*0.5*$E$29*$E$31^2)/($E$32*W36))+($E$32*W36)*(1/(PI()*$X$28*$I$7*0.5*$E$29*$E$31^2)))*($B$32/$E$29)^(3/4)*($E$32/$E$33) -> 0.51548056 | Y36: =((($M$7*0.5*$E$29*$E$31^2)/(W36*$E$32))+(W36*$E$32)*(1/(PI()*$Y$28*$I$7*0.5*$E$29*$E$31^2)))*($B$32/$E$29)^(3/4)*($E$32/$E$33) -> 0.51149045 | Z36: =((($M$7*0.5*$E$29*$E$31^2)/(W36*$E$32))+(W36*$E$32)*(1/(PI()*$Z$28*$I$7*0.5*$E$29*$E$31^2)))*($B$32/$E$29)^(3/4)*($E$32/$E$33) -> 0.50908243 | AD36: =(($AJ$29)/(SQRT(AE36)*SQRT((2/$B$32)*(1/$AD$29))))+($AD$30/$AD$29) -> 0.50406984 | AE36: 300 | AF36: =(($AJ$29)/(SQRT(AG36)*SQRT((2/$B$32)*(1/$AF$29))))+($AF$30/$AF$29) -> 0.53233341 | AG36: 300 | AH36: =(($AJ$29)/(SQRT(AI36)*SQRT((2/$B$32)*(1/$AH$29))))+($AH$30/$AH$29) -> 0.55656236 | AI36: 300 | AO36: =(($AO$30)+2*SQRT(($N$7)/(PI()*$AO$28*$J$7)))*2 -> 0.12226379 | AP36: 200 | AQ36: =(($AO$30)+2*SQRT(($N$7)/(PI()*$AQ$28*$J$7)))*2 -> 0.11242997 | AR36: 200 | AS36: =(($AO$30)+2*SQRT(($N$7)/(PI()*$AS$28*$J$7)))*2 -> 0.10568995 | AT36: 200 | AY36: =(($M$7*0.5*$B$32*$E$31^2)/(AZ36))+AZ36*($AY$30^2/(PI()*$AY$28*$I$7*0.5*$B$32*$E$31^2)) -> 1.1844316 | AZ36: 200 | BA36: =(($M$7*0.5*$B$32*$E$31^2)/(BB36))+BB36*(($AY$30^2)/(PI()*$BA$28*$I$7*0.5*$B$32*$E$31^2)) -> 1.183981 | BB36: 200 | BC36: =(($M$7*0.5*$B$32*$E$31^2)/(BD36))+BD36*(($AY$30^2)/(PI()*$BC$28*$I$7*0.5*$B$32*$E$31^2)) -> 1.1837091 | BD36: 200
O37: 800 | P37: =(($I$12/O37)*($O$27/1.1^2)*1)^-1 -> 0.06659686 | Q37: 800 | R37: =(($I$12/Q37)*($Q$27/1.1^2)*1)^-1 -> 0.06659686 | S37: 800 | T37: =(($I$12/S37)*($S$27/1.1^2)*1)^-1 -> 0.06659686 | W37: 800 | X37: =((($M$7*0.5*$E$29*$E$31^2)/($E$32*W37))+($E$32*W37)*(1/(PI()*$X$28*$I$7*0.5*$E$29*$E$31^2)))*($B$32/$E$29)^(3/4)*($E$32/$E$33) -> 0.45536776 | Y37: =((($M$7*0.5*$E$29*$E$31^2)/(W37*$E$32))+(W37*$E$32)*(1/(PI()*$Y$28*$I$7*0.5*$E$29*$E$31^2)))*($B$32/$E$29)^(3/4)*($E$32/$E$33) -> 0.45080765 | Z37: =((($M$7*0.5*$E$29*$E$31^2)/(W37*$E$32))+(W37*$E$32)*(1/(PI()*$Z$28*$I$7*0.5*$E$29*$E$31^2)))*($B$32/$E$29)^(3/4)*($E$32/$E$33) -> 0.44805562 | AD37: =(($AJ$29)/(SQRT(AE37)*SQRT((2/$B$32)*(1/$AD$29))))+($AD$30/$AD$29) -> 0.44228232 | AE37: 400 | AF37: =(($AJ$29)/(SQRT(AG37)*SQRT((2/$B$32)*(1/$AF$29))))+($AF$30/$AF$29) -> 0.46599864 | AG37: 400 | AH37: =(($AJ$29)/(SQRT(AI37)*SQRT((2/$B$32)*(1/$AH$29))))+($AH$30/$AH$29) -> 0.48646019 | AI37: 400 | AO37: =(($AO$30)+2*SQRT(($N$7)/(PI()*$AO$28*$J$7)))*2 -> 0.12226379 | AP37: 300 | AQ37: =(($AO$30)+2*SQRT(($N$7)/(PI()*$AQ$28*$J$7)))*2 -> 0.11242997 | AR37: 300 | AS37: =(($AO$30)+2*SQRT(($N$7)/(PI()*$AS$28*$J$7)))*2 -> 0.10568995 | AT37: 300 | AY37: =(($M$7*0.5*$B$32*$E$31^2)/(AZ37))+AZ37*($AY$30^2/(PI()*$AY$28*$I$7*0.5*$B$32*$E$31^2)) -> 0.7911395 | AZ37: 300 | BA37: =(($M$7*0.5*$B$32*$E$31^2)/(BB37))+BB37*(($AY$30^2)/(PI()*$BA$28*$I$7*0.5*$B$32*$E$31^2)) -> 0.79046366 | BB37: 300 | BC37: =(($M$7*0.5*$B$32*$E$31^2)/(BD37))+BD37*(($AY$30^2)/(PI()*$BC$28*$I$7*0.5*$B$32*$E$31^2)) -> 0.79005578 | BD37: 300
O38: 900 | P38: =(($I$12/O38)*($O$27/1.1^2)*1)^-1 -> 0.074921468 | Q38: 900 | R38: =(($I$12/Q38)*($Q$27/1.1^2)*1)^-1 -> 0.074921468 | S38: 900 | T38: =(($I$12/S38)*($S$27/1.1^2)*1)^-1 -> 0.074921468 | W38: 900 | X38: =((($M$7*0.5*$E$29*$E$31^2)/($E$32*W38))+($E$32*W38)*(1/(PI()*$X$28*$I$7*0.5*$E$29*$E$31^2)))*($B$32/$E$29)^(3/4)*($E$32/$E$33) -> 0.40912564 | Y38: =((($M$7*0.5*$E$29*$E$31^2)/(W38*$E$32))+(W38*$E$32)*(1/(PI()*$Y$28*$I$7*0.5*$E$29*$E$31^2)))*($B$32/$E$29)^(3/4)*($E$32/$E$33) -> 0.40399551 | Z38: =((($M$7*0.5*$E$29*$E$31^2)/(W38*$E$32))+(W38*$E$32)*(1/(PI()*$Z$28*$I$7*0.5*$E$29*$E$31^2)))*($B$32/$E$29)^(3/4)*($E$32/$E$33) -> 0.40089947 | AD38: =(($AJ$29)/(SQRT(AE38)*SQRT((2/$B$32)*(1/$AD$29))))+($AD$30/$AD$29) -> 0.40011646 | AE38: 500 | AF38: =(($AJ$29)/(SQRT(AG38)*SQRT((2/$B$32)*(1/$AF$29))))+($AF$30/$AF$29) -> 0.42072959 | AG38: 500 | AH38: =(($AJ$29)/(SQRT(AI38)*SQRT((2/$B$32)*(1/$AH$29))))+($AH$30/$AH$29) -> 0.43862013 | AI38: 500 | AO38: =(($AO$30)+2*SQRT(($N$7)/(PI()*$AO$28*$J$7)))*2 -> 0.12226379 | AP38: 400 | AQ38: =(($AO$30)+2*SQRT(($N$7)/(PI()*$AQ$28*$J$7)))*2 -> 0.11242997 | AR38: 400 | AS38: =(($AO$30)+2*SQRT(($N$7)/(PI()*$AS$28*$J$7)))*2 -> 0.10568995 | AT38: 400 | AY38: =(($M$7*0.5*$B$32*$E$31^2)/(AZ38))+AZ38*($AY$30^2/(PI()*$AY$28*$I$7*0.5*$B$32*$E$31^2)) -> 0.59494899 | AZ38: 400 | BA38: =(($M$7*0.5*$B$32*$E$31^2)/(BB38))+BB38*(($AY$30^2)/(PI()*$BA$28*$I$7*0.5*$B$32*$E$31^2)) -> 0.59404787 | BB38: 400 | BC38: =(($M$7*0.5*$B$32*$E$31^2)/(BD38))+BD38*(($AY$30^2)/(PI()*$BC$28*$I$7*0.5*$B$32*$E$31^2)) -> 0.59350404 | BD38: 400
O39: 1000 | P39: =(($I$12/O39)*($O$27/1.1^2)*1)^-1 -> 0.083246075 | Q39: 1000 | R39: =(($I$12/Q39)*($Q$27/1.1^2)*1)^-1 -> 0.083246075 | S39: 1000 | T39: =(($I$12/S39)*($S$27/1.1^2)*1)^-1 -> 0.083246075 | W39: 1000 | X39: =((($M$7*0.5*$E$29*$E$31^2)/($E$32*W39))+($E$32*W39)*(1/(PI()*$X$28*$I$7*0.5*$E$29*$E$31^2)))*($B$32/$E$29)^(3/4)*($E$32/$E$33) -> 0.37259299 | Y39: =((($M$7*0.5*$E$29*$E$31^2)/(W39*$E$32))+(W39*$E$32)*(1/(PI()*$Y$28*$I$7*0.5*$E$29*$E$31^2)))*($B$32/$E$29)^(3/4)*($E$32/$E$33) -> 0.36689284 | Z39: =((($M$7*0.5*$E$29*$E$31^2)/(W39*$E$32))+(W39*$E$32)*(1/(PI()*$Z$28*$I$7*0.5*$E$29*$E$31^2)))*($B$32/$E$29)^(3/4)*($E$32/$E$33) -> 0.3634528 | AD39: =(($AJ$29)/(SQRT(AE39)*SQRT((2/$B$32)*(1/$AD$29))))+($AD$30/$AD$29) -> 0.36899091 | AE39: 600 | AF39: =(($AJ$29)/(SQRT(AG39)*SQRT((2/$B$32)*(1/$AF$29))))+($AF$30/$AF$29) -> 0.38731336 | AG39: 600 | AH39: =(($AJ$29)/(SQRT(AI39)*SQRT((2/$B$32)*(1/$AH$29))))+($AH$30/$AH$29) -> 0.40330606 | AI39: 600 | AO39: =(($AO$30)+2*SQRT(($N$7)/(PI()*$AO$28*$J$7)))*2 -> 0.12226379 | AP39: 500 | AQ39: =(($AO$30)+2*SQRT(($N$7)/(PI()*$AQ$28*$J$7)))*2 -> 0.11242997 | AR39: 500 | AS39: =(($AO$30)+2*SQRT(($N$7)/(PI()*$AS$28*$J$7)))*2 -> 0.10568995 | AT39: 500 | AY39: =(($M$7*0.5*$B$32*$E$31^2)/(AZ39))+AZ39*($AY$30^2/(PI()*$AY$28*$I$7*0.5*$B$32*$E$31^2)) -> 0.47759912 | AZ39: 500 | BA39: =(($M$7*0.5*$B$32*$E$31^2)/(BB39))+BB39*(($AY$30^2)/(PI()*$BA$28*$I$7*0.5*$B$32*$E$31^2)) -> 0.47647271 | BB39: 500 | BC39: =(($M$7*0.5*$B$32*$E$31^2)/(BD39))+BD39*(($AY$30^2)/(PI()*$BC$28*$I$7*0.5*$B$32*$E$31^2)) -> 0.47579292 | BD39: 500
O40: 1100 | P40: =(($I$12/O40)*($O$27/1.1^2)*1)^-1 -> 0.091570683 | Q40: 1100 | R40: =(($I$12/Q40)*($Q$27/1.1^2)*1)^-1 -> 0.091570683 | S40: 1100 | T40: =(($I$12/S40)*($S$27/1.1^2)*1)^-1 -> 0.091570683 | W40: 1100 | X40: =((($M$7*0.5*$E$29*$E$31^2)/($E$32*W40))+($E$32*W40)*(1/(PI()*$X$28*$I$7*0.5*$E$29*$E$31^2)))*($B$32/$E$29)^(3/4)*($E$32/$E$33) -> 0.34312176 | Y40: =((($M$7*0.5*$E$29*$E$31^2)/(W40*$E$32))+(W40*$E$32)*(1/(PI()*$Y$28*$I$7*0.5*$E$29*$E$31^2)))*($B$32/$E$29)^(3/4)*($E$32/$E$33) -> 0.3368516 | Z40: =((($M$7*0.5*$E$29*$E$31^2)/(W40*$E$32))+(W40*$E$32)*(1/(PI()*$Z$28*$I$7*0.5*$E$29*$E$31^2)))*($B$32/$E$29)^(3/4)*($E$32/$E$33) -> 0.33306756 | AD40: =(($AJ$29)/(SQRT(AE40)*SQRT((2/$B$32)*(1/$AD$29))))+($AD$30/$AD$29) -> 0.34480015 | AE40: 700 | AF40: =(($AJ$29)/(SQRT(AG40)*SQRT((2/$B$32)*(1/$AF$29))))+($AF$30/$AF$29) -> 0.36134228 | AG40: 700 | AH40: =(($AJ$29)/(SQRT(AI40)*SQRT((2/$B$32)*(1/$AH$29))))+($AH$30/$AH$29) -> 0.37585999 | AI40: 700 | AO40: =(($AO$30)+2*SQRT(($N$7)/(PI()*$AO$28*$J$7)))*2 -> 0.12226379 | AP40: 600 | AQ40: =(($AO$30)+2*SQRT(($N$7)/(PI()*$AQ$28*$J$7)))*2 -> 0.11242997 | AR40: 600 | AS40: =(($AO$30)+2*SQRT(($N$7)/(PI()*$AS$28*$J$7)))*2 -> 0.10568995 | AT40: 600 | AY40: =(($M$7*0.5*$B$32*$E$31^2)/(AZ40))+AZ40*($AY$30^2/(PI()*$AY$28*$I$7*0.5*$B$32*$E$31^2)) -> 0.39966955 | AZ40: 600 | BA40: =(($M$7*0.5*$B$32*$E$31^2)/(BB40))+BB40*(($AY$30^2)/(PI()*$BA$28*$I$7*0.5*$B$32*$E$31^2)) -> 0.39831787 | BB40: 600 | BC40: =(($M$7*0.5*$B$32*$E$31^2)/(BD40))+BD40*(($AY$30^2)/(PI()*$BC$28*$I$7*0.5*$B$32*$E$31^2)) -> 0.39750212 | BD40: 600
O41: 1200 | P41: =(($I$12/O41)*($O$27/1.1^2)*1)^-1 -> 0.09989529 | Q41: 1200 | R41: =(($I$12/Q41)*($Q$27/1.1^2)*1)^-1 -> 0.09989529 | S41: 1200 | T41: =(($I$12/S41)*($S$27/1.1^2)*1)^-1 -> 0.09989529 | W41: 1200 | X41: =((($M$7*0.5*$E$29*$E$31^2)/($E$32*W41))+($E$32*W41)*(1/(PI()*$X$28*$I$7*0.5*$E$29*$E$31^2)))*($B$32/$E$29)^(3/4)*($E$32/$E$33) -> 0.31894661 | Y41: =((($M$7*0.5*$E$29*$E$31^2)/(W41*$E$32))+(W41*$E$32)*(1/(PI()*$Y$28*$I$7*0.5*$E$29*$E$31^2)))*($B$32/$E$29)^(3/4)*($E$32/$E$33) -> 0.31210643 | Z41: =((($M$7*0.5*$E$29*$E$31^2)/(W41*$E$32))+(W41*$E$32)*(1/(PI()*$Z$28*$I$7*0.5*$E$29*$E$31^2)))*($B$32/$E$29)^(3/4)*($E$32/$E$33) -> 0.30797839 | AD41: =(($AJ$29)/(SQRT(AE41)*SQRT((2/$B$32)*(1/$AD$29))))+($AD$30/$AD$29) -> 0.32530054 | AE41: 800 | AF41: =(($AJ$29)/(SQRT(AG41)*SQRT((2/$B$32)*(1/$AF$29))))+($AF$30/$AF$29) -> 0.34040759 | AG41: 800 | AH41: =(($AJ$29)/(SQRT(AI41)*SQRT((2/$B$32)*(1/$AH$29))))+($AH$30/$AH$29) -> 0.35373634 | AI41: 800 | AO41: =(($AO$30)+2*SQRT(($N$7)/(PI()*$AO$28*$J$7)))*2 -> 0.12226379 | AP41: 700 | AQ41: =(($AO$30)+2*SQRT(($N$7)/(PI()*$AQ$28*$J$7)))*2 -> 0.11242997 | AR41: 700 | AS41: =(($AO$30)+2*SQRT(($N$7)/(PI()*$AS$28*$J$7)))*2 -> 0.10568995 | AT41: 700 | AY41: =(($M$7*0.5*$B$32*$E$31^2)/(AZ41))+AZ41*($AY$30^2/(PI()*$AY$28*$I$7*0.5*$B$32*$E$31^2)) -> 0.34426589 | AZ41: 700 | BA41: =(($M$7*0.5*$B$32*$E$31^2)/(BB41))+BB41*(($AY$30^2)/(PI()*$BA$28*$I$7*0.5*$B$32*$E$31^2)) -> 0.34268892 | BB41: 700 | BC41: =(($M$7*0.5*$B$32*$E$31^2)/(BD41))+BD41*(($AY$30^2)/(PI()*$BC$28*$I$7*0.5*$B$32*$E$31^2)) -> 0.34173722 | BD41: 700
...

Sheet Fuselage
A1: Cross-Section
A2: Name | B2: Sign | C2: Value | D2: Unit | E2: Note | G2: Name | H2: Sign | I2: Value | J2: Unit | K2: Note | O2: NOTE
A3: Number of pax | B3: npax | C3: 150 | D3: - | E3: Req. | H3: df,inner | I3: =4129.158/1000 -> 4.129158 | J3: m | K3: Drawing | L3: For now, I'll guess | O3: Green | P3: Input value
A4: Number of seat abreast per row | B4: nsa | C4: =ROUND(0.45*SQRT($C$3),0) -> 6 | D4: - | E4: - | H4: df,outer | I4: =1.045*$I$3+0.084 -> 4.3989701 | J4: m | K4: - | O4: Yellow | P4: Calculation
A5: Left seat nbr | B5: Left nsa | C5: =ROUND(C4/2,0) -> 3 | D5: - | E5: - | H5: ltailcone | I5: =$C$18*$I$4 -> 14.956498 | J5: m | K5: -
A6: Right seat nbr | B6: Right nsa | C6: =C4-C5 -> 3 | D6: - | E6: - | H6: lnosecone | I6: =$I$4*$C$19 -> 7.9181462 | J6: m | K6: -
A7: Nbr of aisle | B7: naisles | C7: =IF(C4<=6,1,2) -> 1 | D7: - | E7: - | H7: ltail | I7: =C20*I4 -> 7.0383522 | J7: m | K7: -
A8: Correction value | B8: kcabin | C8: 1.08 | D8: - | E8: Estimate | H8: lfuselage | I8: =C9+C17+I7 -> 38.038352 | J8: m | K8: - | N8: Note | O8: Most values are pure guess
A9: Length of full cabin | B9: lcabin | C9: =($C$3/C4)*$C$8 -> 27 | D9: m | E9: - | H9: tfuselage | I9: =(I4-I3)/2 -> 0.13490605 | J9: m | K9: -
A10: Seat pitch | B10: ls | C10: =0.86 -> 0.86 | D10: m | E10: CS25 | H10: wcabin | I10: =C4*C14+(C4+C7+1)*C15+(C7*C13)+2*C16 -> 4.0044 | J10: m | K10: -
A11: Length of passenger cabin | B11: lpax | C11: =C10/C8*C9 -> 21.5 | D11: m | E11: - | H11: wheadroom | I11: =I10-2*(C15+C16)-C14 -> 3.3548 | J11: m | K11: - | P11: Incorrect!
H12: R | I12: =I3/2 -> 2.064579 | J12: m | K12: - | P12: Aero - Transonic
A13: Width of aisle | B13: waisle | C13: 0.51 | D13: m | E13: CS25 | H13: P | I13: =I12-I15-C21 -> 1.039579 | K13: - | P13: Name | Q13: Sign | R13: Value | S13: Unit | T13: Note | U13: Note 2
A14: Width of seat | B14: wseat | C14: 0.508 | D14: m | E14: CS25 | H14: φ | I14: =DEGREES(2*ACOS(1-(I13/I12))) -> 120.46664 | J14: deg | K14: - | Q14: Cdfus | R14: =R15+R24 -> 0.004333645
A15: Width of armrest | B15: warmrest | C15: 0.0508 | D15: m | E15: CS25 | H15: hcentre | I15: =0.825 -> 0.825 | J15: m | K15: - | Q15: CD0fus | R15: =R16*(R17+R21)+R22+R23*R32/R20 -> 0.0043316631
A16: Width of clearance | B16: sclearance | C16: 0.02 | D16: m | E16: Guess | H16: ACC | I16: =0.8*0.5*(I12)^2*(RADIANS(I14)-SIN(RADIANS(I14))) -> 2.1152417 | K16: - | Q16: Rwf | R16: 0.98
A17: Legnth of cockpit | B17: lcockpit | C17: 4 | D17: m | E17: Guess | H17: VCC | I17: =C9*I16*I18 -> 25.700186 | K17: - | Q17: CDffus | R17: =R30*R19/R20 -> 0.0039572731 | T17: M=0.6 | U17: Done
A18: Ratio | B18: ltailcone / df,outer | C18: 3.4 | D18: - | E18: Torenbeek | H18: kCC | I18: 0.45 | K18: - | Q18: Cffus | R18: 0.0024 | T18: M=0.8 | U18: Done
A19: Ratio | B19: lnosecone / df,outer | C19: 1.8 | D19: - | E19: Kroo | H19: VOS | I19: =(2*I22+I20*I21)*C9*I23 -> 7.992 | K19: - | Q19: Swetfus | R19: =(PI()*I4/4)*(1/(3*I6^2)*((4*I6^2+I4^2/4)^1.5-I4^3/8)-I4+4*C9+2*SQRT(I5^2+I4^2/4)) -> 537.27177 | U19: ?
A20: Ratio | B20: ltail / df,outer | C20: 1.6 | D20: - | E20: Roskam | H20: nOS | I20: 0 | K20: - | Q20: S | R20: ='Wing Design'!E8 -> 352.99727 | U20: Done
A21: Height of floor | B21: hfloor | C21: 0.2 | D21: m | E21: ? | H21: AOS,ce | I21: 0.24 | K21: - | Q21: CDpfus | R21: =R30*(60/(I8/I4)^3+0.0025*(I8/I4))*(R19/R20) -> 0.0004527749 | U21: Done
A22: Height of shoulder | B22: hshoulder | C22: 0.9 | D22: m | E22: ? | H22: AOS,lat | I22: 0.2 | K22: - | Q22: CDbfus | R22: =R35*1.1*(R33/I4)^2 -> 9.8161098e-06 | U22: Done
A23: Height of aisle | B23: haisle | C23: 1.9 | D23: m | E23: ? | H23: kOS | I23: 0.74 | K23: - | Q23: Cdwavefus | R23: 0 | T23: M=0.8 no wave | U23: Done
A24: Height of headroom | B24: hheadroom | C24: 1.6 | D24: m | E24: ? | H24: mluggage | I24: 5 | J24: kg | K24: Estimate | Q24: CDLfus | R24: =R25^2*R26/R20 -> 1.9818259e-06
H25: mluggage total | I25: =I24*C3 -> 750 | J25: kg | K25: - | Q25: alpha | R25: =RADIANS(3) -> 0.052359878
H26: density luggage | I26: 170 | J26: kg/m3 | K26: Estimate | Q26: Sbasefus | R26: =R33^2*PI()/4 -> 0.25517586
H27: Vluggage | I27: =I25/I26 -> 4.4117647 | J27: m3 | K27: - | Q27: Re fus | R27: =('TW and WS'!E29*'TW and WS'!E31*Fuselage!I8)/(1.5005*10^-5) -> 2.1862682e+08 | T27: Cruise | U27: Done
H28: mcargo | I28: 20 | J28: kg | K28: Estimate | Q28: Re fus | R28: =(181.051*'TW and WS'!E29*Fuselage!I8)/(1.5005*10^-5) -> 1.6761352e+08 | T28: M=0.6 | U28: Done
H29: mcargo total | I29: =I28*C3 -> 3000 | J29: kg | K29: -
H30: density cargo | I30: 160 | J30: kg/m3 | K30: - | Q30: Cffus | R30: 0.0026 | T30: M=0.6 | U30: Done
H31: Vcargo | I31: =I29/I30 -> 18.75 | J31: m3 | K31: - | Q31: CDbfus | R31: =(0.029*(R33/I4)^3/(R34*(R20/R32))^0.5)*(R32/R20) -> 8.9237362e-06 | T31: Basic / sub-sonic | U31: Done
Q32: Sfus | R32: =(I4/2)^2*PI() -> 15.198191 | U32: Done
G33: Cargo enough? | I33: =IF(I31<I17,"Yes","No") -> Yes | Q33: db | R33: 0.57 | S33: m | U33: Done
Q34: CD0 fus-bas | R34: =R16*R18*(1+60/(I8/I4)^3+0.0025*(I8/I4))*R19/R20 -> 0.0039893973 | U34: Done
Q35: CDb fus / (db/df)^2 | R35: =R31/(R33/I4)^2 -> 0.00053149482 | U35: Done

Sheet Wing Design
B2: Pressure [Pa] | C2: Dynamic Pressure [Pa] | E2: cos Λ c/4 | F2: Λ c/4 [rad]/[deg] | G2: λ | H2: Γ [deg] | I2: Cr [m] | J2: Ct [m] | K2: tan Λ c/2 [rad] | L2: Λ c/2 [rad] | M2: MAC [m] | N2: yMAC [m] | T2: =I8*17.5+(12.5-I8*6.3) -> 20.270829 | W2: XFLR5 With_fuselage_1_working_test
B3: ='TW and WS'!E26 -> 22730.294 | C3: =0.5*1.4*B3*'TW and WS'!C15^2 -> 10183.172 | E3: =0.75*B15/B16 -> 0.84487952 | F3: =ACOS(E3) -> 0.56445642 | G3: =0.2*(2-F4*PI()/180) -> 0.28710872 | H3: =3-ROUND(F4/10,0)+2 -> 2 | I3: =2*E8/((1+G3)*G8) -> 9.6606879 | J3: =I3*G3 -> 2.7736677 | K3: =TAN(F3)-1/F8*(1-G3)/(1+G3) -> 0.5725261 | L3: =ATAN(K3) -> 0.51997309 | M3: =I3*(2/3)*(1+G3+G3^2)/(1+G3) -> 6.8529304 | N3: =G8/2*(I3-M3)/(I3-J3) -> 11.573809 | Q3: =(I3+Q4)/2*5.3 -> 47.151509 | W3: Total area | X3: 519.011
F4: =DEGREES(F3) -> 32.34097 | Q4: =I3-((I3-J3)/H8*6.3) -> 8.1323343 | S4: 5.778 | T4: 2.231 | W4: BDY | X4: 118.6668
S5: 9 | T5: =(T4/S4)*S5 -> 3.4750779 | W5: BLD | X5: 37.4
W6: BDY + BLD | X6: =X4+X5 -> 156.0668
B7: T/W | C7: ='TW and WS'!I16 -> 0.215 | E7: S [m2] | F7: AR | G7: b [m] | H7: b/2 [m] | I7: tan Λ LE [rad] | J7: Λ LE [rad] | K7: Λ LE [deg] | L7: tan Λ TE [rad] | M7: Λ TE [rad] | N7: Λ TE [deg] | W7: WNG OUTBD | X7: =X3-X6 -> 362.9442
B8: W/S | C8: ='TW and WS'!I17 -> 2250 | E8: =C9/C8 -> 352.99727 | F8: ='TW and WS'!C7 -> 9.1323969 | G8: =SQRT(E8*F8) -> 56.777735 | H8: =G8/2 -> 28.388867 | I8: =$K$3-(4/$F$8)*(((0-0.5)*(1-$G$3))/(1+$G$3)) -> 0.693824 | J8: =ATAN(I8) -> 0.60656896 | K8: =DEGREES(J8) -> 34.753842 | L8: =$K$3-(4/$F$8)*(((0-0.5)*(1-$G$3))/(1+$G$3)) -> 0.693824 | M8: =ATAN(L8) -> 0.60656896 | N8: =DEGREES(M8) -> 34.753842 | W8: WNG OVRLAP | X8: =66.7851 -> 66.7851
B9: MTOW | C9: ='Class 1 Weight est.'!M17 -> 794243.86 | I9: =I8*H8 -> 19.696878 | W9: WNG REF | X9: 318.604
B10: V_S | C10: {=SQRT((C8*2)/('TW and WS'!B32*'TW and WS'!A7:B7))} -> 46.0148 | D10: #DIV/0!
E11: CL cruise | F11: t/c | G11: Cl,des | H11: Cl,des,0 | J11: CLα
E12: =C9/(C3*E8) -> 0.22095277 | F12: =MIN((COS(L3))^3*(B15-B16*COS(L3)-0.115*E12^1.5)/(COS(L3)^2),0.18) -> 0.17595744 | G12: =(1.1/('TW and WS'!E29*('TW and WS'!E31*COS('Wing Design'!J8))^2))*('TW and WS'!U18+'TW and WS'!U19) -> 0.33670688 | H12: =G12*SQRT(1-'TW and WS'!C15^2) -> 0.20202413 | J12: =(2*PI()*F8)/(2+SQRT(4+((F8*B18/0.95)^2)*(1+(K3^2/B18^2)))) -> 5.6148549 | K12: 1/rad
J13: =J12*PI()/180 -> 0.097997705 | K13: 1/deg
A14: Constant values
A15: M+ | B15: 0.935
A16: Mdd | B16: ='TW and WS'!C15+0.03 -> 0.83 | T16: for R | U16: R
A17: M | B17: 0.8 | T17: =(F8*G3)/(COS(J8)) -> 3.1912888 | U17: 0.94
A18: β | B18: =SQRT(1-$B$17^2) -> 0.6 | D18: t/c | E18: α0 | F18: α trim | G18: Clmax | H18: Dy | I18: CL/cl | J18: CLmax | K18: d_alfa-stall | L18: a_stall | M18: S_wet_fus | N18: S_wet_wing | O18: S_wet_nac | P18: C_D0 | Q18: A_eff | R18: e | S18: e_2 | T18: e_3
A19: α0 | B19: 63 | C19: yellow | D19: 0.15 | E19: -1.69 | F19: =$E$12/$J$13 + E19 -> 0.56467295 | G19: 1.7 | H19: =1.47 -> 1.47 | I19: 1.05 | J19: =I19*G19 -> 1.785 | K19: 5.5 | L19: =J19/$J$13+E19+K19 -> 22.024712 | M19: 452.63 | N19: =$E$8*2 -> 705.99454 | O19: =2*PI()*1.35*5.1*2 -> 86.519462 | P19: =(0.003*N19+0.0024*M19+O19*0.006)/$E$8 -> 0.010547992 | Q19: =$F$8+(1.9*(2.5/$E$8))*7 -> 9.2265902 | R19: =4.61*(1-0.045*$Q$19^0.68)*(COS($J$8)^0.15)-3.1 -> 0.46338158 | S19: =1/((1+0.12*0.8^2)*(1+(0.142*0.005*(1+1.5*($G$3-0.6)^2)*Q19*(10*D19)^0.33))/(COS($F$3))^2+(0.1*(21+1)/(4+Q19)^0.8)) -> 0.55548208 | T19: =(1.1*$J$12/Q19)/(($U$17*$J$12/Q19)+(1-$U$17)*PI()) -> 0.8801798
B20: 63 | C20: white | D20: 0.1 | E20: -1.55 | F20: =$E$12/$J$13 + E20 -> 0.70467295 | G20: 1.8 | H20: =22/10 -> 2.2 | I20: 0.85 | J20: =I20*G20 -> 1.53 | K20: 5 | L20: =J20/$J$13+E20+K20 -> 19.062611 | M20: 452.63 | N20: =$E$8*2 -> 705.99454 | O20: =2*PI()*1.35*5.1*2 -> 86.519462 | P20: =(0.003*N20+0.0024*M20+O20*0.006)/$E$8 -> 0.010547992 | Q20: =$F$8+(1.9*(2.5/$E$8))*7 -> 9.2265902 | R20: =4.61*(1-0.045*$Q$19^0.68)*(COS($J$8)^0.15)-3.1 -> 0.46338158 | S20: =1/((1+0.12*0.8^2)*(1+(0.142*0.005*(1+1.5*($G$3-0.6)^2)*Q20*(10*D20)^0.33))/(COS($F$3))^2+(0.1*(21+1)/(4+Q20)^0.8)) -> 0.55598319 | T20: =(1.1*$J$12/Q20)/(($U$17*$J$12/Q20)+(1-$U$17)*PI()) -> 0.8801798
A21: α0 | B21: 63 | C21: red | D21: 0.1 | E21: -1.54 | F21: =$E$12/$J$13 + E21 -> 0.71467295 | G21: 1.75 | H21: 2.13 | I21: 0.87 | J21: =I21*G21 -> 1.5225 | K21: 5 | L21: =J21/$J$13+E21+K21 -> 18.996078 | M21: 452.63 | N21: =$E$8*2 -> 705.99454 | O21: =2*PI()*1.35*5.1*2 -> 86.519462 | P21: =(0.003*N21+0.0024*M21+O21*0.006)/$E$8 -> 0.010547992 | Q21: =$F$8+(1.9*(2.5/$E$8))*7 -> 9.2265902 | R21: =4.61*(1-0.045*$Q$19^0.68)*(COS($J$8)^0.15)-3.1 -> 0.46338158 | S21: =1/((1+0.12*0.8^2)*(1+(0.142*0.005*(1+1.5*($G$3-0.6)^2)*Q21*(10*D21)^0.33))/(COS($F$3))^2+(0.1*(21+1)/(4+Q21)^0.8)) -> 0.55598319 | T21: =(1.1*$J$12/Q21)/(($U$17*$J$12/Q21)+(1-$U$17)*PI()) -> 0.8801798
A22: α0 | B22: 63 | C22: grey | D22: 0.1 | E22: -1.5 | F22: =$E$12/$J$13 + E22 -> 0.75467295 | G22: 1.5 | H22: =19.3/10 -> 1.93 | I22: 0.92 | J22: =I22*G22 -> 1.38 | K22: 5 | L22: =J22/$J$13+E22+K22 -> 17.581962 | M22: 452.63 | N22: =$E$8*2 -> 705.99454 | O22: =2*PI()*1.35*5.1*2 -> 86.519462 | P22: =(0.003*N22+0.0024*M22+O22*0.006)/$E$8 -> 0.010547992 | Q22: =$F$8+(1.9*(2.5/$E$8))*7 -> 9.2265902 | R22: =4.61*(1-0.045*$Q$19^0.68)*(COS($J$8)^0.15)-3.1 -> 0.46338158 | S22: =1/((1+0.12*0.8^2)*(1+(0.142*0.005*(1+1.5*($G$3-0.6)^2)*Q22*(10*D22)^0.33))/(COS($F$3))^2+(0.1*(21+1)/(4+Q22)^0.8)) -> 0.55598319 | T22: =(1.1*$J$12/Q22)/(($U$17*$J$12/Q22)+(1-$U$17)*PI()) -> 0.8801798
